nohup: ignoring input
Task exception was never retrieved
future: <Task finished name='Task-4283' coro=<UpdateMethods._dispatch_queue_updates() done, defined at /usr/local/lib/python3.8/dist-packages/telethon/client/updates.py:393> exception=OperationalError('database is locked')>
Traceback (most recent call last):
  File "/usr/local/lib/python3.8/dist-packages/telethon/client/updates.py", line 395, in _dispatch_queue_updates
    await self._dispatch_update(*self._updates_queue.get_nowait())
  File "/usr/local/lib/python3.8/dist-packages/telethon/client/updates.py", line 408, in _dispatch_update
    await self._get_difference(update, channel_id, pts_date)
  File "/usr/local/lib/python3.8/dist-packages/telethon/client/updates.py", line 558, in _get_difference
    result = await self(functions.updates.GetChannelDifferenceRequest(
  File "/usr/local/lib/python3.8/dist-packages/telethon/client/users.py", line 30, in __call__
    return await self._call(self._sender, request, ordered=ordered)
  File "/usr/local/lib/python3.8/dist-packages/telethon/client/users.py", line 85, in _call
    self.session.process_entities(result)
  File "/usr/local/lib/python3.8/dist-packages/telethon/sessions/sqlite.py", line 287, in process_entities
    c.executemany(
sqlite3.OperationalError: database is locked
Unhandled error while processing msgs
Traceback (most recent call last):
  File "/usr/local/lib/python3.8/dist-packages/telethon/network/mtprotosender.py", line 540, in _recv_loop
    await self._process_message(message)
  File "/usr/local/lib/python3.8/dist-packages/telethon/network/mtprotosender.py", line 555, in _process_message
    await handler(message)
  File "/usr/local/lib/python3.8/dist-packages/telethon/network/mtprotosender.py", line 656, in _handle_update
    self._update_callback(message.obj)
  File "/usr/local/lib/python3.8/dist-packages/telethon/client/updates.py", line 304, in _handle_update
    self.session.process_entities(update)
  File "/usr/local/lib/python3.8/dist-packages/telethon/sessions/sqlite.py", line 287, in process_entities
    c.executemany(
sqlite3.OperationalError: database is locked
